<mujoco model="MuJoCo Model">
  <!--Compiler Options-->
  <compiler angle="radian"/>
  <option timestep="0.001" gravity="0 0 -9.81" density="1.225" viscosity="1.8e-05" integrator="RK4" jacobian="sparse">
    <flag energy="enable" contact="enable"/>
  </option>

  <visual>
    <headlight diffuse="0.6 0.6 0.6" ambient="0.3 0.3 0.3" specular="0 0 0"/>
    <rgba haze="0.15 0.25 0.35 1"/>
    <global azimuth="-20" elevation="-20" ellipsoidinertia="true"/>
  </visual>  

  <asset>
    <texture type="skybox" builtin="gradient" rgb1="0.3 0.5 0.7" rgb2="0 0 0" width="512" height="3072"/>
    <texture type="2d" name="groundplane" builtin="checker" mark="edge" rgb1="0.2 0.3 0.4" rgb2="0.1 0.2 0.3"
      markrgb="0.8 0.8 0.8" width="300" height="300"/>
    <material name="groundplane" texture="groundplane" texuniform="true" texrepeat="5 5" reflectance="0.2"/>
  </asset>

  <default>
        <site type="sphere" rgba="1 0 0 1" size="0.005"/>
        <tendon limited="true" width="0.003" rgba="1 1 1 1"/>
        <geom friction=".2"/>
  </default>

  <worldbody>
    <light pos="0 0 1.5" dir="0 0 -1" directional="true"/>
    <geom name="floor" size="0 0 0.05" type="plane" material="groundplane"/>

    <camera name="Upper_view" pos="0.0 0.0 6.0" quat="1 0.0 0.0 0.0" mode="trackcom"/>
    <camera name="Track_view" pos="0 -1 .5" quat="0.707 0.70 0.0 0.0" mode="trackcom"/>

    <!-- System Models -->
    <!-- Block fized postion, free rotation -->
    <body name="block_1" pos="0 0 1">
      <joint pos="0 0 0" type="ball" actuatorfrclimited="false" damping="0.1"/>
      <geom name="block_1" size="0.1 0.2 0.3" type="box" rgba="0 0.9 0 1" mass="1.0"/>
    </body>

    <!-- Free body only in xyz axis -->
    <body name="floating_box" pos="0 1 3">
        <joint name="joint_x" pos="0 0 0" type="slide" axis="1 0 0" limited="true" range="-3 3" damping="100"/>
        <joint name="joint_y" pos="0 0 0" type="slide" axis="0 1 0" limited="true" range="-3 3" damping="100"/>
        <joint name="joint_z" pos="0 0 0" type="slide" axis="0 0 1" limited="true" range="-0.5 0.5" damping="100"/>
      <geom name="floating_box" size="0.2" type="sphere" rgba="1 0 0 1"/>
      <site name="origin0" pos="0 0 0"/>
    </body>

    <!-- Free body -->
    <body name="box_3" pos="0 1 1">
      <joint name="free_joint" pos="0 0 0" type="free" damping="1"/>
      <geom name="box_3" size="0.1 0.1 0.1" type="box" rgba="0 0 1 1"/>
      <site name="insertion0" pos="0.1 0.1 0.1"/>
      <site name="insertion1" pos="-0.1 0.1 0.1"/>
      <site name="insertion2" pos="-0.1 -0.1 0.1"/>
      <site name="insertion3" pos="0.1 -0.1 0.1"/>
    </body>


    <!-- Quadrotor body -->
    <body name="quadrotor" pos="0 0 0" euler="0 0 0">
      <joint name="root_drone" type="free" damping="0.03" armature="0" pos="0 0 0"/>
      <geom name="core" type="box" pos="0 0 0" quat="1. 0. 0. 0" size="0.035 0.035 0.015" rgba="1 1 1 0.7" mass=".84"/>
      <geom name="a00" type="box" pos=".071 0.071 0.0" size="0.05 0.01 0.0025" quat=".924 0.0 0.0 0.383" rgba="1 1 1 0.7" mass=".025"/>
      <geom name="a10" type="box" pos=".071 -0.071 0.0" size="0.05 0.01 0.0025" quat=".383 0.0 0.0 0.924" rgba="1 1 1 0.7" mass=".025"/>
      <geom name="a20" type="box" pos="-0.071 -0.071 0.0" size="0.05 0.01 0.0025" quat="-.383 0.0 0.0 0.924" rgba="1 1 1 0.7" mass=".025"/>
      <geom name="a30" type="box" pos="-.071 0.071 0.0" size="0.05 0.01 0.0025" quat=".924 0.0 0.0 -0.383" rgba="1 1 1 0.7" mass=".025"/>

      <!--   Thruster geometries for collisions since site's are excluded from collision checking   -->
      <geom name="thruster0" type="cylinder" pos=" 0.1 0.1 0.01" size="0.05 0.0025" quat="1.0 0.0 0.0 0." rgba="0.2 0.2 0.2 1" mass=".015"/>
      <geom name="thruster1" type="cylinder" pos=" 0.1 -0.1 0.01" size="0.05 0.0025" quat="1.0 0.0 0.0 0." rgba="0.2 0.2 0.2 1" mass=".015"/>
      <geom name="thruster2" type="cylinder" pos="-0.1 -0.1 0.01" size="0.05 0.0025" quat="1.0 0.0 0.0 0." rgba="0.2 0.2 0.2 1" mass=".015"/>
      <geom name="thruster3" type="cylinder" pos="-0.1 0.1 0.01" size="0.05 0.0025" quat="1.0 0.0 0.0 0." rgba="0.2 0.2 0.2 1" mass=".015"/>

      <!--  Representation of the body frame   -->
      <site name="qcX" type="box" pos="0.05 0.0 0.0" size="0.05 0.005 0.005" quat=" 1.000 0.0 0.0 0." rgba="1 0 0 1"/>
      <site name="qcY" type="box" pos="0.0 0.05 0.0" size="0.05 0.005 0.005" quat=" 0.707 0.0 0.0 0.707" rgba="0 1 0 1"/>
      <site name="qcZ" type="box" pos="0.0 0.0 0.05" size="0.05 0.005 0.005" quat="-0.707 0.0 0.707 0." rgba="0 0 1 1"/>

      <!--   Actuator sites to attach actuators, make it invisible   -->
      <site name="thrust" type="box" pos="0 0 0" size="0.035 0.035 0.015" quat="1.0 0.0 0.0 0." rgba="0 1 1 0"/>
      <site name="rateX" type="box" pos="0 0 0" quat="1. 0. 0. 0." size="0.06 0.035 0.015" rgba="0 1 1 0"/>
      <site name="rateY" type="box" pos="0 0 0" quat="1. 0. 0. 0." size="0.06 0.035 0.015" rgba="0 1 1 0"/>
      <site name="rateZ" type="box" pos="0 0 0" quat="1. 0. 0. 0." size="0.06 0.035 0.015" rgba="0 1 1 0"/>

    </body>
  </worldbody>


      <!--  Actuators of the system   -->
<actuator>
    <motor ctrllimited="true" ctrlrange="0.0 20.0" gear="0 0. 1. 0. 0. 0." site="thrust"/>
    <motor ctrllimited="true" ctrlrange="-5 5" gear="0. 0. 0. 1. 0. 0." site="rateX"/>
    <motor ctrllimited="true" ctrlrange="-5 5" gear="0. 0. 0. 0. 1. 0." site="rateY"/>
    <motor ctrllimited="true" ctrlrange="-5 5" gear="0. 0. 0. 0. 0. 1." site="rateZ"/>
</actuator>
<sensor>
    <framequat name="quat_drone" objtype="geom" reftype="body" refname="world" objname="core" noise="0.000"/>
    <framepos name="position_drone" objtype="geom" objname="core" noise="0.00"/>
    <velocimeter name="linear_velocity_drone" site="thrust" noise="0.0"/>
    <gyro name="angular_velocity_drone" site="thrust" noise="0.00"/>
</sensor>

    <tendon>
        <spatial name="rope0" range="0 2">
            <site site="origin0"/>
            <site site="insertion0"/>
        </spatial>
    </tendon>

</mujoco>
